Workbook

Sheet Model Inputs & Assumptions
A1: PAID DISPLAY PLANNER · MODEL INPUTS & ASSUMPTIONS
A2: Every input the model consumes. Blue = user input · Grey = Notion-loaded · Green = derived by formula · Orange = manual override. This workbook never writes back to Notion.
A4: 1 · CAMPAIGN & MODEL SETTINGS | O4: LEGEND
A5: Campaign name | C5: Ultramarin — German Retail Launch | F5: Notion campaign record. | P5: User input | Q5: Typed here, or written by the Streamlit app.
A6: Scenario name | C6: Base case — 8 activations, Q1 2027 | F6: Free text. One workbook per scenario. | P6: Notion-loaded | Q6: Read from Notion when the scenario was built.
A7: Analysis date | C7: 46273 | F7: Date the scenario was run. | P7: Derived | Q7: Excel formula. Locked while the sheet is protected.
A8: Target currency | C8: EUR | F8: All campaign totals are reported in this currency. | P8: Manual override | Q8: Deliberately replaces a loaded value — say why in Notes.
A9: Number of simulation iterations | C9: 500 | F9: Rows per activation on Activation Detail, and rows on Simulation Detail.
A10: Random seed | C10: 20260908 | F10: Seed behind the frozen shocks on Activation Detail. | O10: Derived cells are locked; input, loaded and override cells stay editable while sheet protection is on.
A11: Minimum historical sample for full weight | C11: 5 | F11: Completed activations needed before an inventory estimate is treated as fully historical.
A12: Notes | C12: Illustrative worked example. Streamlit overwrites the blue and grey ranges; every green cell recalculates.
A14: 2 · INVENTORY PERFORMANCE — HISTORICAL ESTIMATES & FALLBACK ASSUMPTIONS
A15: One row per Inventory item. Estimates are built from completed activations with valid performance data; where history is thin the Inventory fallback is used, and the Basis column states which applies. Impressions use the historical median; CTR = clicks ÷ impressions; view rate = video views ÷ impressions.
A16: Inventory ID | B16: Inventory name | C16: Estimation method | D16: Historical activation count | E16: Hist. activations with impressions | F16: Hist. activations with video views | G16: Hist. activations with clicks | H16: Hist. median impressions | I16: Hist. total impressions | J16: Hist. total video views | K16: Hist. total clicks | L16: Hist. view rate % | M16: Hist. CTR % | N16: Fallback impressions | O16: Fallback view rate % | P16: Fallback CTR % | Q16: Impressions Sigma % | R16: View rate Sigma % | S16: CTR Sigma % | T16: Weight — impressions | U16: Weight — view rate | V16: Weight — CTR | W16: Expected impressions (used) | X16: Expected view rate % (used) | Y16: Expected CTR % (used) | Z16: Basis | AA16: Notes
A17: INV-01 | B17: finanzen.net — Display Network | C17: Historical | D17: 9 | E17: 9 | F17: 0 | G17: 9 | H17: 460000 | I17: 4120000 | J17: 0 | K17: 6180 | L17: =IF($I17=0,0,$J17/$I17) -> 0 | M17: =IF($I17=0,0,$K17/$I17) -> 0.0015 | N17: 400000 | O17: 0 | P17: 0.0012 | Q17: 0.18 | R17: 0.25 | S17: 0.22 | T17: =IF($C17="Fallback",0,IF($E17=0,0,IF($C17="Historical",1,MIN(1,$E17/$C$11)))) -> 1 | U17: =IF($C17="Fallback",0,IF($F17=0,0,IF($C17="Historical",1,MIN(1,$F17/$C$11)))) -> 0 | V17: =IF($C17="Fallback",0,IF($G17=0,0,IF($C17="Historical",1,MIN(1,$G17/$C$11)))) -> 1 | W17: =$T17*$H17+(1-$T17)*$N17 -> 460000 | X17: =$U17*$L17+(1-$U17)*$O17 -> 0 | Y17: =$V17*$M17+(1-$V17)*$P17 -> 0.0015 | Z17: =IF($T17=1,"Historical",IF($T17=0,"Fallback","Blended "&TEXT($T17,"0%")&" historical")) -> Historical | AA17: Nine completed display activations since Jan 2025. No video inventory.
A18: INV-02 | B18: Handelsblatt — Native Article | C18: Blended | D18: 3 | E18: 3 | F18: 0 | G18: 3 | H18: 210000 | I18: 640000 | J18: 0 | K18: 1980 | L18: =IF($I18=0,0,$J18/$I18) -> 0 | M18: =IF($I18=0,0,$K18/$I18) -> 0.00309375 | N18: 180000 | O18: 0 | P18: 0.0028 | Q18: 0.22 | R18: 0.25 | S18: 0.26 | T18: =IF($C18="Fallback",0,IF($E18=0,0,IF($C18="Historical",1,MIN(1,$E18/$C$11)))) -> 0.6 | U18: =IF($C18="Fallback",0,IF($F18=0,0,IF($C18="Historical",1,MIN(1,$F18/$C$11)))) -> 0 | V18: =IF($C18="Fallback",0,IF($G18=0,0,IF($C18="Historical",1,MIN(1,$G18/$C$11)))) -> 0.6 | W18: =$T18*$H18+(1-$T18)*$N18 -> 198000 | X18: =$U18*$L18+(1-$U18)*$O18 -> 0 | Y18: =$V18*$M18+(1-$V18)*$P18 -> 0.00297625 | Z18: =IF($T18=1,"Historical",IF($T18=0,"Fallback","Blended "&TEXT($T18,"0%")&" historical")) -> Blended 60% historical | AA18: Only three completed activations, so history is blended with the rate card fallback.
A19: INV-03 | B19: extraETF — Newsletter Takeover | C19: Historical | D19: 6 | E19: 6 | F19: 0 | G19: 6 | H19: 88000 | I19: 540000 | J19: 0 | K19: 4320 | L19: =IF($I19=0,0,$J19/$I19) -> 0 | M19: =IF($I19=0,0,$K19/$I19) -> 0.008 | N19: 75000 | O19: 0 | P19: 0.007 | Q19: 0.12 | R19: 0.25 | S19: 0.15 | T19: =IF($C19="Fallback",0,IF($E19=0,0,IF($C19="Historical",1,MIN(1,$E19/$C$11)))) -> 1 | U19: =IF($C19="Fallback",0,IF($F19=0,0,IF($C19="Historical",1,MIN(1,$F19/$C$11)))) -> 0 | V19: =IF($C19="Fallback",0,IF($G19=0,0,IF($C19="Historical",1,MIN(1,$G19/$C$11)))) -> 1 | W19: =$T19*$H19+(1-$T19)*$N19 -> 88000 | X19: =$U19*$L19+(1-$U19)*$O19 -> 0 | Y19: =$V19*$M19+(1-$V19)*$P19 -> 0.008 | Z19: =IF($T19=1,"Historical",IF($T19=0,"Fallback","Blended "&TEXT($T19,"0%")&" historical")) -> Historical | AA19: Stable list size; six sends with full delivery reporting.
A20: INV-04 | B20: YouTube — Finfluencer Network Pre-roll | C20: Historical | D20: 5 | E20: 5 | F20: 5 | G20: 5 | H20: 480000 | I20: 2300000 | J20: 1357000 | K20: 11500 | L20: =IF($I20=0,0,$J20/$I20) -> 0.59 | M20: =IF($I20=0,0,$K20/$I20) -> 0.005 | N20: 400000 | O20: 0.55 | P20: 0.0045 | Q20: 0.28 | R20: 0.14 | S20: 0.24 | T20: =IF($C20="Fallback",0,IF($E20=0,0,IF($C20="Historical",1,MIN(1,$E20/$C$11)))) -> 1 | U20: =IF($C20="Fallback",0,IF($F20=0,0,IF($C20="Historical",1,MIN(1,$F20/$C$11)))) -> 1 | V20: =IF($C20="Fallback",0,IF($G20=0,0,IF($C20="Historical",1,MIN(1,$G20/$C$11)))) -> 1 | W20: =$T20*$H20+(1-$T20)*$N20 -> 480000 | X20: =$U20*$L20+(1-$U20)*$O20 -> 0.59 | Y20: =$V20*$M20+(1-$V20)*$P20 -> 0.005 | Z20: =IF($T20=1,"Historical",IF($T20=0,"Fallback","Blended "&TEXT($T20,"0%")&" historical")) -> Historical | AA20: Five pre-roll flights with view-through reporting from the network.
A21: INV-05 | B21: Trade Republic — In-App Display | C21: Fallback | D21: 0 | E21: 0 | F21: 0 | G21: 0 | H21: 0 | I21: 0 | J21: 0 | K21: 0 | L21: =IF($I21=0,0,$J21/$I21) -> 0 | M21: =IF($I21=0,0,$K21/$I21) -> 0 | N21: 1200000 | O21: 0 | P21: 0.0035 | Q21: 0.3 | R21: 0.25 | S21: 0.3 | T21: =IF($C21="Fallback",0,IF($E21=0,0,IF($C21="Historical",1,MIN(1,$E21/$C$11)))) -> 0 | U21: =IF($C21="Fallback",0,IF($F21=0,0,IF($C21="Historical",1,MIN(1,$F21/$C$11)))) -> 0 | V21: =IF($C21="Fallback",0,IF($G21=0,0,IF($C21="Historical",1,MIN(1,$G21/$C$11)))) -> 0 | W21: =$T21*$H21+(1-$T21)*$N21 -> 1200000 | X21: =$U21*$L21+(1-$U21)*$O21 -> 0 | Y21: =$V21*$M21+(1-$V21)*$P21 -> 0.0035 | Z21: =IF($T21=1,"Historical",IF($T21=0,"Fallback","Blended "&TEXT($T21,"0%")&" historical")) -> Fallback | AA21: No completed activations. Volumes and CTR are the platform's published rate-card assumptions.
A22: INV-06 | B22: Meta — Feed Video (Investor Lookalike) | C22: Historical | D22: 8 | E22: 8 | F22: 8 | G22: 8 | H22: 520000 | I22: 3900000 | J22: 897000 | K22: 23400 | L22: =IF($I22=0,0,$J22/$I22) -> 0.23 | M22: =IF($I22=0,0,$K22/$I22) -> 0.006 | N22: 450000 | O22: 0.2 | P22: 0.0055 | Q22: 0.2 | R22: 0.16 | S22: 0.18 | T22: =IF($C22="Fallback",0,IF($E22=0,0,IF($C22="Historical",1,MIN(1,$E22/$C$11)))) -> 1 | U22: =IF($C22="Fallback",0,IF($F22=0,0,IF($C22="Historical",1,MIN(1,$F22/$C$11)))) -> 1 | V22: =IF($C22="Fallback",0,IF($G22=0,0,IF($C22="Historical",1,MIN(1,$G22/$C$11)))) -> 1 | W22: =$T22*$H22+(1-$T22)*$N22 -> 520000 | X22: =$U22*$L22+(1-$U22)*$O22 -> 0.23 | Y22: =$V22*$M22+(1-$V22)*$P22 -> 0.006 | Z22: =IF($T22=1,"Historical",IF($T22=0,"Fallback","Blended "&TEXT($T22,"0%")&" historical")) -> Historical | AA22: Eight completed lookalike flights; view rate is 3-second views over impressions.
A23: INV-07 | B23: justETF — Sponsored Listing | C23: Blended | D23: 2 | E23: 2 | F23: 0 | G23: 2 | H23: 96000 | I23: 190000 | J23: 0 | K23: 1330 | L23: =IF($I23=0,0,$J23/$I23) -> 0 | M23: =IF($I23=0,0,$K23/$I23) -> 0.007 | N23: 85000 | O23: 0 | P23: 0.0065 | Q23: 0.15 | R23: 0.25 | S23: 0.2 | T23: =IF($C23="Fallback",0,IF($E23=0,0,IF($C23="Historical",1,MIN(1,$E23/$C$11)))) -> 0.4 | U23: =IF($C23="Fallback",0,IF($F23=0,0,IF($C23="Historical",1,MIN(1,$F23/$C$11)))) -> 0 | V23: =IF($C23="Fallback",0,IF($G23=0,0,IF($C23="Historical",1,MIN(1,$G23/$C$11)))) -> 0.4 | W23: =$T23*$H23+(1-$T23)*$N23 -> 89400 | X23: =$U23*$L23+(1-$U23)*$O23 -> 0 | Y23: =$V23*$M23+(1-$V23)*$P23 -> 0.0067 | Z23: =IF($T23=1,"Historical",IF($T23=0,"Fallback","Blended "&TEXT($T23,"0%")&" historical")) -> Blended 40% historical | AA23: Two completed listings only; blended with the publisher's fallback estimate.
A25: 3 · ACTIVATIONS
A26: One row per Activation, whether it already sits on the Campaign in Notion (Campaign activation) or was added to this scenario from Inventory (Scenario activation). Performance expectations are inherited from the Inventory table above; product economics are inherited from the Products table below and are never re-entered here. The three conversion rates are additive paths — an activation may convert off impressions, views, clicks, or any combination.
A27: Activation ID | B27: Activation name | C27: Source | D27: Inventory ID | E27: Inventory name | F27: Format | G27: Status | H27: Pricing model | I27: Cost | J27: Cost currency | K27: FX rate to target currency | L27: Selected Product | M27: Product name | N27: Conversion / impression % | O27: Conversion / view % | P27: Conversion / click % | Q27: Conversion Sigma % | R27: Estimation method | S27: Expected impressions | T27: Impressions Sigma % | U27: Expected view rate % | V27: View rate Sigma % | W27: Expected CTR % | X27: CTR Sigma % | Y27: Notes
A28: ACT-01 | B28: finanzen.net — Q1 Awareness Burst | C28: Campaign activation | D28: INV-01 | E28: =INDEX($B$17:$B$23,MATCH($D28,$A$17:$A$23,0)) -> finanzen.net — Display Network | F28: Display banner | G28: Confirmed | H28: CPM | I28: 6.5 | J28: EUR | K28: =INDEX($C$47:$C$50,MATCH($J28,$A$47:$A$50,0)) -> 1 | L28: PRD-EUAI | M28: =INDEX($B$40:$B$42,MATCH($L28,$A$40:$A$42,0)) -> Ultramarin Europe AI UCITS ETF (EUAI) | N28: 0 | O28: 0 | P28: 0.03 | Q28: 0.3 | R28: =INDEX($Z$17:$Z$23,MATCH($D28,$A$17:$A$23,0)) -> Historical | S28: =INDEX($W$17:$W$23,MATCH($D28,$A$17:$A$23,0)) -> 460000 | T28: =INDEX($Q$17:$Q$23,MATCH($D28,$A$17:$A$23,0)) -> 0.18 | U28: =INDEX($X$17:$X$23,MATCH($D28,$A$17:$A$23,0)) -> 0 | V28: =INDEX($R$17:$R$23,MATCH($D28,$A$17:$A$23,0)) -> 0.25 | W28: =INDEX($Y$17:$Y$23,MATCH($D28,$A$17:$A$23,0)) -> 0.0015 | X28: =INDEX($S$17:$S$23,MATCH($D28,$A$17:$A$23,0)) -> 0.22 | Y28: Booked Jan–Feb. CPM is the agreed net rate.
A29: ACT-02 | B29: Handelsblatt — Native Explainer | C29: Campaign activation | D29: INV-02 | E29: =INDEX($B$17:$B$23,MATCH($D29,$A$17:$A$23,0)) -> Handelsblatt — Native Article | F29: Native article | G29: Confirmed | H29: Fixed | I29: 6500 | J29: EUR | K29: =INDEX($C$47:$C$50,MATCH($J29,$A$47:$A$50,0)) -> 1 | L29: PRD-EUAI | M29: =INDEX($B$40:$B$42,MATCH($L29,$A$40:$A$42,0)) -> Ultramarin Europe AI UCITS ETF (EUAI) | N29: 0 | O29: 0 | P29: 0.05 | Q29: 0.3 | R29: =INDEX($Z$17:$Z$23,MATCH($D29,$A$17:$A$23,0)) -> Blended 60% historical | S29: =INDEX($W$17:$W$23,MATCH($D29,$A$17:$A$23,0)) -> 198000 | T29: =INDEX($Q$17:$Q$23,MATCH($D29,$A$17:$A$23,0)) -> 0.22 | U29: =INDEX($X$17:$X$23,MATCH($D29,$A$17:$A$23,0)) -> 0 | V29: =INDEX($R$17:$R$23,MATCH($D29,$A$17:$A$23,0)) -> 0.25 | W29: =INDEX($Y$17:$Y$23,MATCH($D29,$A$17:$A$23,0)) -> 0.00297625 | X29: =INDEX($S$17:$S$23,MATCH($D29,$A$17:$A$23,0)) -> 0.26 | Y29: Fixed placement fee, two-week run.
A30: ACT-03 | B30: extraETF — Newsletter Takeover | C30: Campaign activation | D30: INV-03 | E30: =INDEX($B$17:$B$23,MATCH($D30,$A$17:$A$23,0)) -> extraETF — Newsletter Takeover | F30: Newsletter takeover | G30: Confirmed | H30: Fixed | I30: 6900 | J30: EUR | K30: =INDEX($C$47:$C$50,MATCH($J30,$A$47:$A$50,0)) -> 1 | L30: PRD-USIQ | M30: =INDEX($B$40:$B$42,MATCH($L30,$A$40:$A$42,0)) -> Ultramarin US Innovation UCITS ETF (USIQ) | N30: 0 | O30: 0 | P30: 0.065 | Q30: 0.25 | R30: =INDEX($Z$17:$Z$23,MATCH($D30,$A$17:$A$23,0)) -> Historical | S30: =INDEX($W$17:$W$23,MATCH($D30,$A$17:$A$23,0)) -> 88000 | T30: =INDEX($Q$17:$Q$23,MATCH($D30,$A$17:$A$23,0)) -> 0.12 | U30: =INDEX($X$17:$X$23,MATCH($D30,$A$17:$A$23,0)) -> 0 | V30: =INDEX($R$17:$R$23,MATCH($D30,$A$17:$A$23,0)) -> 0.25 | W30: =INDEX($Y$17:$Y$23,MATCH($D30,$A$17:$A$23,0)) -> 0.008 | X30: =INDEX($S$17:$S$23,MATCH($D30,$A$17:$A$23,0)) -> 0.15 | Y30: Single send to the full German list.
A31: ACT-04 | B31: YouTube — Finfluencer Pre-roll | C31: Campaign activation | D31: INV-04 | E31: =INDEX($B$17:$B$23,MATCH($D31,$A$17:$A$23,0)) -> YouTube — Finfluencer Network Pre-roll | F31: Video pre-roll | G31: Planned | H31: CPM | I31: 12.4 | J31: USD | K31: =INDEX($C$47:$C$50,MATCH($J31,$A$47:$A$50,0)) -> 0.915 | L31: PRD-USIQ | M31: =INDEX($B$40:$B$42,MATCH($L31,$A$40:$A$42,0)) -> Ultramarin US Innovation UCITS ETF (USIQ) | N31: 0 | O31: 8e-05 | P31: 0.015 | Q31: 0.35 | R31: =INDEX($Z$17:$Z$23,MATCH($D31,$A$17:$A$23,0)) -> Historical | S31: =INDEX($W$17:$W$23,MATCH($D31,$A$17:$A$23,0)) -> 480000 | T31: =INDEX($Q$17:$Q$23,MATCH($D31,$A$17:$A$23,0)) -> 0.28 | U31: =INDEX($X$17:$X$23,MATCH($D31,$A$17:$A$23,0)) -> 0.59 | V31: =INDEX($R$17:$R$23,MATCH($D31,$A$17:$A$23,0)) -> 0.14 | W31: =INDEX($Y$17:$Y$23,MATCH($D31,$A$17:$A$23,0)) -> 0.005 | X31: =INDEX($S$17:$S$23,MATCH($D31,$A$17:$A$23,0)) -> 0.24 | Y31: Priced in USD by the network; converted at the FX table rate.
A32: ACT-05 | B32: Trade Republic — In-App Display | C32: Campaign activation | D32: INV-05 | E32: =INDEX($B$17:$B$23,MATCH($D32,$A$17:$A$23,0)) -> Trade Republic — In-App Display | F32: In-app display | G32: Planned | H32: CPM | I32: 12 | J32: EUR | K32: =INDEX($C$47:$C$50,MATCH($J32,$A$47:$A$50,0)) -> 1 | L32: PRD-SP01 | M32: =INDEX($B$40:$B$42,MATCH($L32,$A$40:$A$42,0)) -> EUAI Savings Plan (monthly) | N32: 0 | O32: 0 | P32: 0.045 | Q32: 0.28 | R32: =INDEX($Z$17:$Z$23,MATCH($D32,$A$17:$A$23,0)) -> Fallback | S32: =INDEX($W$17:$W$23,MATCH($D32,$A$17:$A$23,0)) -> 1200000 | T32: =INDEX($Q$17:$Q$23,MATCH($D32,$A$17:$A$23,0)) -> 0.3 | U32: =INDEX($X$17:$X$23,MATCH($D32,$A$17:$A$23,0)) -> 0 | V32: =INDEX($R$17:$R$23,MATCH($D32,$A$17:$A$23,0)) -> 0.25 | W32: =INDEX($Y$17:$Y$23,MATCH($D32,$A$17:$A$23,0)) -> 0.0035 | X32: =INDEX($S$17:$S$23,MATCH($D32,$A$17:$A$23,0)) -> 0.3 | Y32: Rate-card CPM; no completed history on this inventory yet.
A33: ACT-06 | B33: Trade Republic — Savings Plan Push | C33: Scenario activation | D33: INV-05 | E33: =INDEX($B$17:$B$23,MATCH($D33,$A$17:$A$23,0)) -> Trade Republic — In-App Display | F33: In-app display | G33: Proposed | H33: Fixed | I33: 25000 | J33: EUR | K33: =INDEX($C$47:$C$50,MATCH($J33,$A$47:$A$50,0)) -> 1 | L33: PRD-SP01 | M33: =INDEX($B$40:$B$42,MATCH($L33,$A$40:$A$42,0)) -> EUAI Savings Plan (monthly) | N33: 0 | O33: 0 | P33: 0.055 | Q33: 0.28 | R33: =INDEX($Z$17:$Z$23,MATCH($D33,$A$17:$A$23,0)) -> Fallback | S33: =INDEX($W$17:$W$23,MATCH($D33,$A$17:$A$23,0)) -> 1200000 | T33: =INDEX($Q$17:$Q$23,MATCH($D33,$A$17:$A$23,0)) -> 0.3 | U33: =INDEX($X$17:$X$23,MATCH($D33,$A$17:$A$23,0)) -> 0 | V33: =INDEX($R$17:$R$23,MATCH($D33,$A$17:$A$23,0)) -> 0.25 | W33: =INDEX($Y$17:$Y$23,MATCH($D33,$A$17:$A$23,0)) -> 0.0035 | X33: =INDEX($S$17:$S$23,MATCH($D33,$A$17:$A$23,0)) -> 0.3 | Y33: Scenario only. Fixed sponsorship of the savings-plan carousel.
A34: ACT-07 | B34: Meta — Lookalike Feed Video | C34: Scenario activation | D34: INV-06 | E34: =INDEX($B$17:$B$23,MATCH($D34,$A$17:$A$23,0)) -> Meta — Feed Video (Investor Lookalike) | F34: Social feed video | G34: Proposed | H34: CPC | I34: 1.85 | J34: EUR | K34: =INDEX($C$47:$C$50,MATCH($J34,$A$47:$A$50,0)) -> 1 | L34: PRD-USIQ | M34: =INDEX($B$40:$B$42,MATCH($L34,$A$40:$A$42,0)) -> Ultramarin US Innovation UCITS ETF (USIQ) | N34: 0 | O34: 8e-05 | P34: 0.02 | Q34: 0.32 | R34: =INDEX($Z$17:$Z$23,MATCH($D34,$A$17:$A$23,0)) -> Historical | S34: =INDEX($W$17:$W$23,MATCH($D34,$A$17:$A$23,0)) -> 520000 | T34: =INDEX($Q$17:$Q$23,MATCH($D34,$A$17:$A$23,0)) -> 0.2 | U34: =INDEX($X$17:$X$23,MATCH($D34,$A$17:$A$23,0)) -> 0.23 | V34: =INDEX($R$17:$R$23,MATCH($D34,$A$17:$A$23,0)) -> 0.16 | W34: =INDEX($Y$17:$Y$23,MATCH($D34,$A$17:$A$23,0)) -> 0.006 | X34: =INDEX($S$17:$S$23,MATCH($D34,$A$17:$A$23,0)) -> 0.18 | Y34: Scenario only. Cost scales with clicks, so cost risk tracks CTR.
A35: ACT-08 | B35: justETF — Sponsored Listing | C35: Campaign activation | D35: INV-07 | E35: =INDEX($B$17:$B$23,MATCH($D35,$A$17:$A$23,0)) -> justETF — Sponsored Listing | F35: Sponsored listing | G35: Confirmed | H35: Fixed | I35: 7400 | J35: GBP | K35: =INDEX($C$47:$C$50,MATCH($J35,$A$47:$A$50,0)) -> 1.172 | L35: PRD-EUAI | M35: =INDEX($B$40:$B$42,MATCH($L35,$A$40:$A$42,0)) -> Ultramarin Europe AI UCITS ETF (EUAI) | N35: 0 | O35: 0 | P35: 0.07 | Q35: 0.26 | R35: =INDEX($Z$17:$Z$23,MATCH($D35,$A$17:$A$23,0)) -> Blended 40% historical | S35: =INDEX($W$17:$W$23,MATCH($D35,$A$17:$A$23,0)) -> 89400 | T35: =INDEX($Q$17:$Q$23,MATCH($D35,$A$17:$A$23,0)) -> 0.15 | U35: =INDEX($X$17:$X$23,MATCH($D35,$A$17:$A$23,0)) -> 0 | V35: =INDEX($R$17:$R$23,MATCH($D35,$A$17:$A$23,0)) -> 0.25 | W35: =INDEX($Y$17:$Y$23,MATCH($D35,$A$17:$A$23,0)) -> 0.0067 | X35: =INDEX($S$17:$S$23,MATCH($D35,$A$17:$A$23,0)) -> 0.2 | Y35: Contracted in GBP; converted at the FX table rate.
A37: 4 · PRODUCTS
A38: Product economics are held once, here, and never repeated as Activation inputs. LTV is derived, not editable: Derived LTV = Average purchase amount × Gross margin % of assets × Expected holding period (years).
A39: Product ID | B39: Product name | C39: Product currency | D39: Average purchase amount | E39: Gross margin % of assets | F39: Expected holding period (years) | G39: Derived LTV | H39: FX rate to target currency | I39: Notes
A40: PRD-EUAI | B40: Ultramarin Europe AI UCITS ETF (EUAI) | C40: EUR | D40: 8500 | E40: 0.0045 | F40: 5 | G40: =$D40*$E40*$F40 -> 191.25 | H40: =INDEX($C$47:$C$50,MATCH($C40,$A$47:$A$50,0)) -> 1 | I40: Lump-sum buyer. Margin is the retained share of the TER.
A41: PRD-USIQ | B41: Ultramarin US Innovation UCITS ETF (USIQ) | C41: EUR | D41: 7200 | E41: 0.0049 | F41: 4.5 | G41: =$D41*$E41*$F41 -> 158.76 | H41: =INDEX($C$47:$C$50,MATCH($C41,$A$47:$A$50,0)) -> 1 | I41: Lump-sum buyer. Shorter observed holding period than EUAI.
A42: PRD-SP01 | B42: EUAI Savings Plan (monthly) | C42: EUR | D42: 5400 | E42: 0.003 | F42: 7 | G42: =$D42*$E42*$F42 -> 113.4 | H42: =INDEX($C$47:$C$50,MATCH($C42,$A$47:$A$50,0)) -> 1 | I42: Three years of contributions at €150/month; longer holding period, lower margin.
A44: 5 · FX ASSUMPTIONS
A45: Every rate used anywhere in the model is stated here. Nothing else converts currency. A rate flagged as a manual override is shown in orange and must carry a reason in Notes.
...

Sheet Performance Summary
A1: PAID DISPLAY PLANNER · PERFORMANCE SUMMARY
A2: Scenario outputs across the full simulation. Every figure on this sheet is a formula over Simulation Detail and Activation Detail — change an input and this sheet moves with it.
A4: CAMPAIGN | F4: MEDIAN CONVERSIONS | H4: MEDIAN COST | J4: MEDIAN LTV VALUE | L4: MEDIAN ROI
A5: Campaign name | B5: ='Model Inputs & Assumptions'!$C$5 -> Ultramarin — German Retail Launch | F5: =$C$20 -> 672.47297 | H5: =$C$22 -> 74891.067 | J5: =$C$24 -> 92220.177 | L5: =$C$25 -> 1.2201032
A6: Scenario name | B6: ='Model Inputs & Assumptions'!$C$6 -> Base case — 8 activations, Q1 2027
A7: Target currency | B7: ='Model Inputs & Assumptions'!$C$8 -> EUR
A8: Number of Activations | B8: =COUNTA('Model Inputs & Assumptions'!$A$28:$A$35) -> 8
A9: Number of Products | B9: =COUNTA('Model Inputs & Assumptions'!$A$40:$A$42) -> 3
A10: Number of simulation iterations | B10: ='Model Inputs & Assumptions'!$C$9 -> 500
A12: CAMPAIGN PERFORMANCE — SIMULATED DISTRIBUTION
A13: Quartiles across every simulation iteration. Q1 is the weak quarter of outcomes, Q3 the strong quarter — read the spread, not just the median.
A14: Metric | B14: Q1 / P25 | C14: Median | D14: Q3 / P75 | E14: Basis
A15: Impressions | B15: =QUARTILE('Simulation Detail'!$B$4:$B$503,1) -> 3856387.2 | C15: =QUARTILE('Simulation Detail'!$B$4:$B$503,2) -> 4203700 | D15: =QUARTILE('Simulation Detail'!$B$4:$B$503,3) -> 4605720.8 | E15: Sum of activation impressions per iteration
A16: Video views | B16: =QUARTILE('Simulation Detail'!$C$4:$C$503,1) -> 337909.75 | C16: =QUARTILE('Simulation Detail'!$C$4:$C$503,2) -> 390631.5 | D16: =QUARTILE('Simulation Detail'!$C$4:$C$503,3) -> 458881 | E16: Impressions × view rate
A17: View rate % | B17: =QUARTILE('Simulation Detail'!$K$4:$K$503,1) -> 0.080279898 | C17: =QUARTILE('Simulation Detail'!$K$4:$K$503,2) -> 0.093857273 | D17: =QUARTILE('Simulation Detail'!$K$4:$K$503,3) -> 0.11033841 | E17: Campaign views ÷ campaign impressions
A18: Clicks | B18: =QUARTILE('Simulation Detail'!$D$4:$D$503,1) -> 14457.5 | C18: =QUARTILE('Simulation Detail'!$D$4:$D$503,2) -> 16214.5 | D18: =QUARTILE('Simulation Detail'!$D$4:$D$503,3) -> 18214 | E18: Impressions × CTR
A19: CTR % | B19: =QUARTILE('Simulation Detail'!$L$4:$L$503,1) -> 0.0035407704 | C19: =QUARTILE('Simulation Detail'!$L$4:$L$503,2) -> 0.0038473585 | D19: =QUARTILE('Simulation Detail'!$L$4:$L$503,3) -> 0.0041582841 | E19: Campaign clicks ÷ campaign impressions
A20: Conversions | B20: =QUARTILE('Simulation Detail'!$E$4:$E$503,1) -> 578.75899 | C20: =QUARTILE('Simulation Detail'!$E$4:$E$503,2) -> 672.47297 | D20: =QUARTILE('Simulation Detail'!$E$4:$E$503,3) -> 768.42851 | E20: Per-impression, per-view and per-click paths, summed
A21: Flows | B21: =QUARTILE('Simulation Detail'!$G$4:$G$503,1) -> 3695745.6 | C21: =QUARTILE('Simulation Detail'!$G$4:$G$503,2) -> 4266162.4 | D21: =QUARTILE('Simulation Detail'!$G$4:$G$503,3) -> 4777142.4 | E21: Conversions × average purchase amount
A22: Cost | B22: =QUARTILE('Simulation Detail'!$F$4:$F$503,1) -> 72107.317 | C22: =QUARTILE('Simulation Detail'!$F$4:$F$503,2) -> 74891.067 | D22: =QUARTILE('Simulation Detail'!$F$4:$F$503,3) -> 78721.696 | E22: Deterministic: fixed, CPM × impressions, or CPC × clicks
A23: Cost per conversion | B23: =QUARTILE('Simulation Detail'!$J$4:$J$503,1) -> 99.935558 | C23: =QUARTILE('Simulation Detail'!$J$4:$J$503,2) -> 112.00024 | D23: =QUARTILE('Simulation Detail'!$J$4:$J$503,3) -> 130.54938 | E23: Total cost ÷ total conversions
A24: LTV value | B24: =QUARTILE('Simulation Detail'!$H$4:$H$503,1) -> 79832.419 | C24: =QUARTILE('Simulation Detail'!$H$4:$H$503,2) -> 92220.177 | D24: =QUARTILE('Simulation Detail'!$H$4:$H$503,3) -> 102946.9 | E24: Conversions × derived LTV
A25: ROI | B25: =QUARTILE('Simulation Detail'!$I$4:$I$503,1) -> 1.0633622 | C25: =QUARTILE('Simulation Detail'!$I$4:$I$503,2) -> 1.2201032 | D25: =QUARTILE('Simulation Detail'!$I$4:$I$503,3) -> 1.3440347 | E25: LTV value ÷ cost
A26: PRODUCT PERFORMANCE
A27: Where a campaign promotes more than one Product, this splits the outcome by Product. Each activation's conversions and cost are attributed to the Product it sells, then quartiled across the same iterations. Product rows sum to the campaign on any single iteration; medians do not add up, because the median iteration differs from one Product to the next.
A28: Product name | B28: Product ID | C28: Activations | D28: Derived LTV (target currency) | E28: Conversions — Q1 | F28: Conversions — median | G28: Conversions — Q3 | H28: Flows — median | I28: LTV value — median | J28: Cost — median | K28: ROI — Q1 | L28: ROI — median | M28: ROI — Q3 | N28: Cost per conversion — median
A29: ='Model Inputs & Assumptions'!$B$40 -> Ultramarin Europe AI UCITS ETF (EUAI) | B29: ='Model Inputs & Assumptions'!$A$40 -> PRD-EUAI | C29: =COUNTIF('Model Inputs & Assumptions'!$L$28:$L$35,$B29) -> 3 | D29: ='Model Inputs & Assumptions'!$G$40*'Model Inputs & Assumptions'!$H$40 -> 191.25 | E29: =QUARTILE('Simulation Detail'!$N$4:$N$503,1) -> 77.33713 | F29: =QUARTILE('Simulation Detail'!$N$4:$N$503,2) -> 90.825758 | G29: =QUARTILE('Simulation Detail'!$N$4:$N$503,3) -> 104.79424 | H29: =QUARTILE('Simulation Detail'!$O$4:$O$503,2) -> 772018.94 | I29: =QUARTILE('Simulation Detail'!$P$4:$P$503,2) -> 17370.426 | J29: =QUARTILE('Simulation Detail'!$Q$4:$Q$503,2) -> 18120.79 | K29: =QUARTILE('Simulation Detail'!$R$4:$R$503,1) -> 0.80855461 | L29: =QUARTILE('Simulation Detail'!$R$4:$R$503,2) -> 0.96350431 | M29: =QUARTILE('Simulation Detail'!$R$4:$R$503,3) -> 1.1025261 | N29: =QUARTILE('Simulation Detail'!$S$4:$S$503,2) -> 198.49434
A30: ='Model Inputs & Assumptions'!$B$41 -> Ultramarin US Innovation UCITS ETF (USIQ) | B30: ='Model Inputs & Assumptions'!$A$41 -> PRD-USIQ | C30: =COUNTIF('Model Inputs & Assumptions'!$L$28:$L$35,$B30) -> 3 | D30: ='Model Inputs & Assumptions'!$G$41*'Model Inputs & Assumptions'!$H$41 -> 158.76 | E30: =QUARTILE('Simulation Detail'!$T$4:$T$503,1) -> 146.08335 | F30: =QUARTILE('Simulation Detail'!$T$4:$T$503,2) -> 170.31682 | G30: =QUARTILE('Simulation Detail'!$T$4:$T$503,3) -> 203.61462 | H30: =QUARTILE('Simulation Detail'!$U$4:$U$503,2) -> 1226281.1 | I30: =QUARTILE('Simulation Detail'!$V$4:$V$503,2) -> 27039.498 | J30: =QUARTILE('Simulation Detail'!$W$4:$W$503,2) -> 17936.239 | K30: =QUARTILE('Simulation Detail'!$X$4:$X$503,1) -> 1.3223368 | L30: =QUARTILE('Simulation Detail'!$X$4:$X$503,2) -> 1.5058488 | M30: =QUARTILE('Simulation Detail'!$X$4:$X$503,3) -> 1.721524 | N30: =QUARTILE('Simulation Detail'!$Y$4:$Y$503,2) -> 105.42926
A31: ='Model Inputs & Assumptions'!$B$42 -> EUAI Savings Plan (monthly) | B31: ='Model Inputs & Assumptions'!$A$42 -> PRD-SP01 | C31: =COUNTIF('Model Inputs & Assumptions'!$L$28:$L$35,$B31) -> 2 | D31: ='Model Inputs & Assumptions'!$G$42*'Model Inputs & Assumptions'!$H$42 -> 113.4 | E31: =QUARTILE('Simulation Detail'!$Z$4:$Z$503,1) -> 303.9668 | F31: =QUARTILE('Simulation Detail'!$Z$4:$Z$503,2) -> 403.92343 | G31: =QUARTILE('Simulation Detail'!$Z$4:$Z$503,3) -> 495.45247 | H31: =QUARTILE('Simulation Detail'!$AA$4:$AA$503,2) -> 2181186.5 | I31: =QUARTILE('Simulation Detail'!$AB$4:$AB$503,2) -> 45804.917 | J31: =QUARTILE('Simulation Detail'!$AC$4:$AC$503,2) -> 38719.9 | K31: =QUARTILE('Simulation Detail'!$AD$4:$AD$503,1) -> 0.90210048 | L31: =QUARTILE('Simulation Detail'!$AD$4:$AD$503,2) -> 1.1695623 | M31: =QUARTILE('Simulation Detail'!$AD$4:$AD$503,3) -> 1.418326 | N31: =QUARTILE('Simulation Detail'!$AE$4:$AE$503,2) -> 96.959434
A33: ACTIVATION PERFORMANCE
A34: Per-activation medians and quartiles across the same iterations. Expected impressions, view rate and CTR are the pre-simulation estimates; everything from Conversions rightward is simulated.
A35: Activation name | B35: Source | C35: Inventory | D35: Product | E35: Estimation method | F35: Expected impressions | G35: Expected view rate % | H35: Expected CTR % | I35: Conversions — median | J35: Conversions — Q1 | K35: Conversions — Q3 | L35: Flows — median | M35: LTV value — median | N35: Cost — median | O35: ROI — median | P35: Cost per conversion — median
A36: ='Model Inputs & Assumptions'!$B$28 -> finanzen.net — Q1 Awareness Burst | B36: ='Model Inputs & Assumptions'!$C$28 -> Campaign activation | C36: ='Model Inputs & Assumptions'!$E$28 -> finanzen.net — Display Network | D36: ='Model Inputs & Assumptions'!$M$28 -> Ultramarin Europe AI UCITS ETF (EUAI) | E36: ='Model Inputs & Assumptions'!$R$28 -> Historical | F36: ='Model Inputs & Assumptions'!$S$28 -> 460000 | G36: ='Model Inputs & Assumptions'!$U$28 -> 0 | H36: ='Model Inputs & Assumptions'!$W$28 -> 0.0015 | I36: =QUARTILE('Activation Detail'!$H$4:$H$503,2) -> 19.518176 | J36: =QUARTILE('Activation Detail'!$H$4:$H$503,1) -> 14.125988 | K36: =QUARTILE('Activation Detail'!$H$4:$H$503,3) -> 25.513437 | L36: =QUARTILE('Activation Detail'!$J$4:$J$503,2) -> 165904.5 | M36: =QUARTILE('Activation Detail'!$K$4:$K$503,2) -> 3732.8512 | N36: =QUARTILE('Activation Detail'!$I$4:$I$503,2) -> 2947.9905 | O36: =QUARTILE('Activation Detail'!$L$4:$L$503,2) -> 1.2433591 | P36: =QUARTILE('Activation Detail'!$M$4:$M$503,2) -> 153.81883
A37: ='Model Inputs & Assumptions'!$B$29 -> Handelsblatt — Native Explainer | B37: ='Model Inputs & Assumptions'!$C$29 -> Campaign activation | C37: ='Model Inputs & Assumptions'!$E$29 -> Handelsblatt — Native Article | D37: ='Model Inputs & Assumptions'!$M$29 -> Ultramarin Europe AI UCITS ETF (EUAI) | E37: ='Model Inputs & Assumptions'!$R$29 -> Blended 60% historical | F37: ='Model Inputs & Assumptions'!$S$29 -> 198000 | G37: ='Model Inputs & Assumptions'!$U$29 -> 0 | H37: ='Model Inputs & Assumptions'!$W$29 -> 0.00297625 | I37: =QUARTILE('Activation Detail'!$H$504:$H$1003,2) -> 26.780834 | J37: =QUARTILE('Activation Detail'!$H$504:$H$1003,1) -> 19.57061 | K37: =QUARTILE('Activation Detail'!$H$504:$H$1003,3) -> 36.838124 | L37: =QUARTILE('Activation Detail'!$J$504:$J$1003,2) -> 227637.09 | M37: =QUARTILE('Activation Detail'!$K$504:$K$1003,2) -> 5121.8345 | N37: =QUARTILE('Activation Detail'!$I$504:$I$1003,2) -> 6500 | O37: =QUARTILE('Activation Detail'!$L$504:$L$1003,2) -> 0.78797453 | P37: =QUARTILE('Activation Detail'!$M$504:$M$1003,2) -> 242.71142
A38: ='Model Inputs & Assumptions'!$B$30 -> extraETF — Newsletter Takeover | B38: ='Model Inputs & Assumptions'!$C$30 -> Campaign activation | C38: ='Model Inputs & Assumptions'!$E$30 -> extraETF — Newsletter Takeover | D38: ='Model Inputs & Assumptions'!$M$30 -> Ultramarin US Innovation UCITS ETF (USIQ) | E38: ='Model Inputs & Assumptions'!$R$30 -> Historical | F38: ='Model Inputs & Assumptions'!$S$30 -> 88000 | G38: ='Model Inputs & Assumptions'!$U$30 -> 0 | H38: ='Model Inputs & Assumptions'!$W$30 -> 0.008 | I38: =QUARTILE('Activation Detail'!$H$1004:$H$1503,2) -> 42.895994 | J38: =QUARTILE('Activation Detail'!$H$1004:$H$1503,1) -> 34.653487 | K38: =QUARTILE('Activation Detail'!$H$1004:$H$1503,3) -> 53.850907 | L38: =QUARTILE('Activation Detail'!$J$1004:$J$1503,2) -> 308851.15 | M38: =QUARTILE('Activation Detail'!$K$1004:$K$1503,2) -> 6810.168 | N38: =QUARTILE('Activation Detail'!$I$1004:$I$1503,2) -> 6900 | O38: =QUARTILE('Activation Detail'!$L$1004:$L$1503,2) -> 0.98698086 | P38: =QUARTILE('Activation Detail'!$M$1004:$M$1503,2) -> 160.8544
A39: ='Model Inputs & Assumptions'!$B$31 -> YouTube — Finfluencer Pre-roll | B39: ='Model Inputs & Assumptions'!$C$31 -> Campaign activation | C39: ='Model Inputs & Assumptions'!$E$31 -> YouTube — Finfluencer Network Pre-roll | D39: ='Model Inputs & Assumptions'!$M$31 -> Ultramarin US Innovation UCITS ETF (USIQ) | E39: ='Model Inputs & Assumptions'!$R$31 -> Historical | F39: ='Model Inputs & Assumptions'!$S$31 -> 480000 | G39: ='Model Inputs & Assumptions'!$U$31 -> 0.59 | H39: ='Model Inputs & Assumptions'!$W$31 -> 0.005 | I39: =QUARTILE('Activation Detail'!$H$1504:$H$2003,2) -> 52.210963 | J39: =QUARTILE('Activation Detail'!$H$1504:$H$2003,1) -> 37.148157 | K39: =QUARTILE('Activation Detail'!$H$1504:$H$2003,3) -> 71.519458 | L39: =QUARTILE('Activation Detail'!$J$1504:$J$2003,2) -> 375918.93 | M39: =QUARTILE('Activation Detail'!$K$1504:$K$2003,2) -> 8289.0125 | N39: =QUARTILE('Activation Detail'!$I$1504:$I$2003,2) -> 5252.2166 | O39: =QUARTILE('Activation Detail'!$L$1504:$L$2003,2) -> 1.5503401 | P39: =QUARTILE('Activation Detail'!$M$1504:$M$2003,2) -> 102.40336
A40: ='Model Inputs & Assumptions'!$B$32 -> Trade Republic — In-App Display | B40: ='Model Inputs & Assumptions'!$C$32 -> Campaign activation | C40: ='Model Inputs & Assumptions'!$E$32 -> Trade Republic — In-App Display | D40: ='Model Inputs & Assumptions'!$M$32 -> EUAI Savings Plan (monthly) | E40: ='Model Inputs & Assumptions'!$R$32 -> Fallback | F40: ='Model Inputs & Assumptions'!$S$32 -> 1200000 | G40: ='Model Inputs & Assumptions'!$U$32 -> 0 | H40: ='Model Inputs & Assumptions'!$W$32 -> 0.0035 | I40: =QUARTILE('Activation Detail'!$H$2004:$H$2503,2) -> 158.18074 | J40: =QUARTILE('Activation Detail'!$H$2004:$H$2503,1) -> 118.74938 | K40: =QUARTILE('Activation Detail'!$H$2004:$H$2503,3) -> 224.92216 | L40: =QUARTILE('Activation Detail'!$J$2004:$J$2503,2) -> 854175.97 | M40: =QUARTILE('Activation Detail'!$K$2004:$K$2503,2) -> 17937.695 | N40: =QUARTILE('Activation Detail'!$I$2004:$I$2503,2) -> 13719.9 | O40: =QUARTILE('Activation Detail'!$L$2004:$L$2503,2) -> 1.3574929 | P40: =QUARTILE('Activation Detail'!$M$2004:$M$2503,2) -> 83.537212
A41: ='Model Inputs & Assumptions'!$B$33 -> Trade Republic — Savings Plan Push | B41: ='Model Inputs & Assumptions'!$C$33 -> Scenario activation | C41: ='Model Inputs & Assumptions'!$E$33 -> Trade Republic — In-App Display | D41: ='Model Inputs & Assumptions'!$M$33 -> EUAI Savings Plan (monthly) | E41: ='Model Inputs & Assumptions'!$R$33 -> Fallback | F41: ='Model Inputs & Assumptions'!$S$33 -> 1200000 | G41: ='Model Inputs & Assumptions'!$U$33 -> 0 | H41: ='Model Inputs & Assumptions'!$W$33 -> 0.0035 | I41: =QUARTILE('Activation Detail'!$H$2504:$H$3003,2) -> 208.36121 | J41: =QUARTILE('Activation Detail'!$H$2504:$H$3003,1) -> 150.97454 | K41: =QUARTILE('Activation Detail'!$H$2504:$H$3003,3) -> 294.08108 | L41: =QUARTILE('Activation Detail'!$J$2504:$J$3003,2) -> 1125150.5 | M41: =QUARTILE('Activation Detail'!$K$2504:$K$3003,2) -> 23628.161 | N41: =QUARTILE('Activation Detail'!$I$2504:$I$3003,2) -> 25000 | O41: =QUARTILE('Activation Detail'!$L$2504:$L$3003,2) -> 0.94512644 | P41: =QUARTILE('Activation Detail'!$M$2504:$M$3003,2) -> 119.98395
A42: ='Model Inputs & Assumptions'!$B$34 -> Meta — Lookalike Feed Video | B42: ='Model Inputs & Assumptions'!$C$34 -> Scenario activation | C42: ='Model Inputs & Assumptions'!$E$34 -> Meta — Feed Video (Investor Lookalike) | D42: ='Model Inputs & Assumptions'!$M$34 -> Ultramarin US Innovation UCITS ETF (USIQ) | E42: ='Model Inputs & Assumptions'!$R$34 -> Historical | F42: ='Model Inputs & Assumptions'!$S$34 -> 520000 | G42: ='Model Inputs & Assumptions'!$U$34 -> 0.23 | H42: ='Model Inputs & Assumptions'!$W$34 -> 0.006 | I42: =QUARTILE('Activation Detail'!$H$3004:$H$3503,2) -> 67.890477 | J42: =QUARTILE('Activation Detail'!$H$3004:$H$3503,1) -> 51.038048 | K42: =QUARTILE('Activation Detail'!$H$3004:$H$3503,3) -> 89.094446 | L42: =QUARTILE('Activation Detail'!$J$3004:$J$3503,2) -> 488811.44 | M42: =QUARTILE('Activation Detail'!$K$3004:$K$3503,2) -> 10778.292 | N42: =QUARTILE('Activation Detail'!$I$3004:$I$3503,2) -> 5541.675 | O42: =QUARTILE('Activation Detail'!$L$3004:$L$3503,2) -> 1.9410073 | P42: =QUARTILE('Activation Detail'!$M$3004:$M$3503,2) -> 81.792588
A43: ='Model Inputs & Assumptions'!$B$35 -> justETF — Sponsored Listing | B43: ='Model Inputs & Assumptions'!$C$35 -> Campaign activation | C43: ='Model Inputs & Assumptions'!$E$35 -> justETF — Sponsored Listing | D43: ='Model Inputs & Assumptions'!$M$35 -> Ultramarin Europe AI UCITS ETF (EUAI) | E43: ='Model Inputs & Assumptions'!$R$35 -> Blended 40% historical | F43: ='Model Inputs & Assumptions'!$S$35 -> 89400 | G43: ='Model Inputs & Assumptions'!$U$35 -> 0 | H43: ='Model Inputs & Assumptions'!$W$35 -> 0.0067 | I43: =QUARTILE('Activation Detail'!$H$3504:$H$4003,2) -> 38.898777 | J43: =QUARTILE('Activation Detail'!$H$3504:$H$4003,1) -> 31.418156 | K43: =QUARTILE('Activation Detail'!$H$3504:$H$4003,3) -> 51.116493 | L43: =QUARTILE('Activation Detail'!$J$3504:$J$4003,2) -> 330639.61 | M43: =QUARTILE('Activation Detail'!$K$3504:$K$4003,2) -> 7439.3912 | N43: =QUARTILE('Activation Detail'!$I$3504:$I$4003,2) -> 8672.8 | O43: =QUARTILE('Activation Detail'!$L$3504:$L$4003,2) -> 0.85778424 | P43: =QUARTILE('Activation Detail'!$M$3504:$M$4003,2) -> 222.95817
...

Sheet Activation Detail
A1: ACTIVATION DETAIL · ONE ROW PER SIMULATION ITERATION PER ACTIVATION
A2: 500 iterations × 8 activations. Every column is a formula reading the inputs sheet; change an assumption there and this recalculates. | N2: Product key — drives the per-product roll-up. | P2: Frozen standard-normal shocks drawn from the random seed — replace these to re-randomise.
A3: Iteration | B3: Activation | C3: Impressions | D3: View rate | E3: Views | F3: CTR | G3: Clicks | H3: Conversions | I3: Cost | J3: Flows | K3: LTV value | L3: ROI | M3: Cost per conversion | N3: Product | P3: z — impressions | Q3: z — view rate | R3: z — CTR | S3: z — conversion
A4: 1 | B4: ='Model Inputs & Assumptions'!$B$28 -> finanzen.net — Q1 Awareness Burst | C4: =ROUND(MAX(0,'Model Inputs & Assumptions'!$S$28*EXP('Model Inputs & Assumptions'!$T$28*P4-'Model Inputs & Assumptions'!$T$28^2/2)),0) -> 444863 | D4: =MIN(1,'Model Inputs & Assumptions'!$U$28*EXP('Model Inputs & Assumptions'!$V$28*Q4-'Model Inputs & Assumptions'!$V$28^2/2)) -> 0 | E4: =ROUND(C4*D4,0) -> 0 | F4: =MIN(1,'Model Inputs & Assumptions'!$W$28*EXP('Model Inputs & Assumptions'!$X$28*R4-'Model Inputs & Assumptions'!$X$28^2/2)) -> 0.0016255104 | G4: =ROUND(C4*F4,0) -> 723 | H4: =MAX(0,(C4*'Model Inputs & Assumptions'!$N$28+E4*'Model Inputs & Assumptions'!$O$28+G4*'Model Inputs & Assumptions'!$P$28)*EXP('Model Inputs & Assumptions'!$Q$28*S4-'Model Inputs & Assumptions'!$Q$28^2/2)) -> 15.100555 | I4: =IF('Model Inputs & Assumptions'!$H$28="Fixed",'Model Inputs & Assumptions'!$I$28*'Model Inputs & Assumptions'!$K$28,IF('Model Inputs & Assumptions'!$H$28="CPM",'Model Inputs & Assumptions'!$I$28*'Model Inputs & Assumptions'!$K$28*C4/1000,IF('Model Inputs & Assumptions'!$H$28="CPC",'Model Inputs & Assumptions'!$I$28*'Model Inputs & Assumptions'!$K$28*G4,0))) -> 2891.6095 | J4: =H4*INDEX('Model Inputs & Assumptions'!$D$40:$D$42,MATCH('Model Inputs & Assumptions'!$L$28,'Model Inputs & Assumptions'!$A$40:$A$42,0))*INDEX('Model Inputs & Assumptions'!$H$40:$H$42,MATCH('Model Inputs & Assumptions'!$L$28,'Model Inputs & Assumptions'!$A$40:$A$42,0)) -> 128354.72 | K4: =H4*INDEX('Model Inputs & Assumptions'!$G$40:$G$42,MATCH('Model Inputs & Assumptions'!$L$28,'Model Inputs & Assumptions'!$A$40:$A$42,0))*INDEX('Model Inputs & Assumptions'!$H$40:$H$42,MATCH('Model Inputs & Assumptions'!$L$28,'Model Inputs & Assumptions'!$A$40:$A$42,0)) -> 2887.9812 | L4: =IFERROR(K4/I4,0) -> 0.99874524 | M4: =IFERROR(I4/H4,0) -> 191.49027 | N4: ='Model Inputs & Assumptions'!$L$28 -> PRD-EUAI | P4: -0.095892 | Q4: 0.236141 | R4: 0.475258 | S4: -1.057066
A5: 2 | B5: ='Model Inputs & Assumptions'!$B$28 -> finanzen.net — Q1 Awareness Burst | C5: =ROUND(MAX(0,'Model Inputs & Assumptions'!$S$28*EXP('Model Inputs & Assumptions'!$T$28*P5-'Model Inputs & Assumptions'!$T$28^2/2)),0) -> 436496 | D5: =MIN(1,'Model Inputs & Assumptions'!$U$28*EXP('Model Inputs & Assumptions'!$V$28*Q5-'Model Inputs & Assumptions'!$V$28^2/2)) -> 0 | E5: =ROUND(C5*D5,0) -> 0 | F5: =MIN(1,'Model Inputs & Assumptions'!$W$28*EXP('Model Inputs & Assumptions'!$X$28*R5-'Model Inputs & Assumptions'!$X$28^2/2)) -> 0.0012918047 | G5: =ROUND(C5*F5,0) -> 564 | H5: =MAX(0,(C5*'Model Inputs & Assumptions'!$N$28+E5*'Model Inputs & Assumptions'!$O$28+G5*'Model Inputs & Assumptions'!$P$28)*EXP('Model Inputs & Assumptions'!$Q$28*S5-'Model Inputs & Assumptions'!$Q$28^2/2)) -> 17.110049 | I5: =IF('Model Inputs & Assumptions'!$H$28="Fixed",'Model Inputs & Assumptions'!$I$28*'Model Inputs & Assumptions'!$K$28,IF('Model Inputs & Assumptions'!$H$28="CPM",'Model Inputs & Assumptions'!$I$28*'Model Inputs & Assumptions'!$K$28*C5/1000,IF('Model Inputs & Assumptions'!$H$28="CPC",'Model Inputs & Assumptions'!$I$28*'Model Inputs & Assumptions'!$K$28*G5,0))) -> 2837.224 | J5: =H5*INDEX('Model Inputs & Assumptions'!$D$40:$D$42,MATCH('Model Inputs & Assumptions'!$L$28,'Model Inputs & Assumptions'!$A$40:$A$42,0))*INDEX('Model Inputs & Assumptions'!$H$40:$H$42,MATCH('Model Inputs & Assumptions'!$L$28,'Model Inputs & Assumptions'!$A$40:$A$42,0)) -> 145435.42 | K5: =H5*INDEX('Model Inputs & Assumptions'!$G$40:$G$42,MATCH('Model Inputs & Assumptions'!$L$28,'Model Inputs & Assumptions'!$A$40:$A$42,0))*INDEX('Model Inputs & Assumptions'!$H$40:$H$42,MATCH('Model Inputs & Assumptions'!$L$28,'Model Inputs & Assumptions'!$A$40:$A$42,0)) -> 3272.2969 | L5: =IFERROR(K5/I5,0) -> 1.1533446 | M5: =IFERROR(I5/H5,0) -> 165.82208 | N5: ='Model Inputs & Assumptions'!$L$28 -> PRD-EUAI | P5: -0.201376 | Q5: -0.247078 | R5: -0.569204 | S5: 0.187232
A6: 3 | B6: ='Model Inputs & Assumptions'!$B$28 -> finanzen.net — Q1 Awareness Burst | C6: =ROUND(MAX(0,'Model Inputs & Assumptions'!$S$28*EXP('Model Inputs & Assumptions'!$T$28*P6-'Model Inputs & Assumptions'!$T$28^2/2)),0) -> 442060 | D6: =MIN(1,'Model Inputs & Assumptions'!$U$28*EXP('Model Inputs & Assumptions'!$V$28*Q6-'Model Inputs & Assumptions'!$V$28^2/2)) -> 0 | E6: =ROUND(C6*D6,0) -> 0 | F6: =MIN(1,'Model Inputs & Assumptions'!$W$28*EXP('Model Inputs & Assumptions'!$X$28*R6-'Model Inputs & Assumptions'!$X$28^2/2)) -> 0.0018749675 | G6: =ROUND(C6*F6,0) -> 829 | H6: =MAX(0,(C6*'Model Inputs & Assumptions'!$N$28+E6*'Model Inputs & Assumptions'!$O$28+G6*'Model Inputs & Assumptions'!$P$28)*EXP('Model Inputs & Assumptions'!$Q$28*S6-'Model Inputs & Assumptions'!$Q$28^2/2)) -> 23.263401 | I6: =IF('Model Inputs & Assumptions'!$H$28="Fixed",'Model Inputs & Assumptions'!$I$28*'Model Inputs & Assumptions'!$K$28,IF('Model Inputs & Assumptions'!$H$28="CPM",'Model Inputs & Assumptions'!$I$28*'Model Inputs & Assumptions'!$K$28*C6/1000,IF('Model Inputs & Assumptions'!$H$28="CPC",'Model Inputs & Assumptions'!$I$28*'Model Inputs & Assumptions'!$K$28*G6,0))) -> 2873.39 | J6: =H6*INDEX('Model Inputs & Assumptions'!$D$40:$D$42,MATCH('Model Inputs & Assumptions'!$L$28,'Model Inputs & Assumptions'!$A$40:$A$42,0))*INDEX('Model Inputs & Assumptions'!$H$40:$H$42,MATCH('Model Inputs & Assumptions'!$L$28,'Model Inputs & Assumptions'!$A$40:$A$42,0)) -> 197738.91 | K6: =H6*INDEX('Model Inputs & Assumptions'!$G$40:$G$42,MATCH('Model Inputs & Assumptions'!$L$28,'Model Inputs & Assumptions'!$A$40:$A$42,0))*INDEX('Model Inputs & Assumptions'!$H$40:$H$42,MATCH('Model Inputs & Assumptions'!$L$28,'Model Inputs & Assumptions'!$A$40:$A$42,0)) -> 4449.1255 | L6: =IFERROR(K6/I6,0) -> 1.548389 | M6: =IFERROR(I6/H6,0) -> 123.51547 | N6: ='Model Inputs & Assumptions'!$L$28 -> PRD-EUAI | P6: -0.13101 | Q6: 0.526583 | R6: 1.12421 | S6: -0.072603
A7: 4 | B7: ='Model Inputs & Assumptions'!$B$28 -> finanzen.net — Q1 Awareness Burst | C7: =ROUND(MAX(0,'Model Inputs & Assumptions'!$S$28*EXP('Model Inputs & Assumptions'!$T$28*P7-'Model Inputs & Assumptions'!$T$28^2/2)),0) -> 394495 | D7: =MIN(1,'Model Inputs & Assumptions'!$U$28*EXP('Model Inputs & Assumptions'!$V$28*Q7-'Model Inputs & Assumptions'!$V$28^2/2)) -> 0 | E7: =ROUND(C7*D7,0) -> 0 | F7: =MIN(1,'Model Inputs & Assumptions'!$W$28*EXP('Model Inputs & Assumptions'!$X$28*R7-'Model Inputs & Assumptions'!$X$28^2/2)) -> 0.0013668261 | G7: =ROUND(C7*F7,0) -> 539 | H7: =MAX(0,(C7*'Model Inputs & Assumptions'!$N$28+E7*'Model Inputs & Assumptions'!$O$28+G7*'Model Inputs & Assumptions'!$P$28)*EXP('Model Inputs & Assumptions'!$Q$28*S7-'Model Inputs & Assumptions'!$Q$28^2/2)) -> 13.874076 | I7: =IF('Model Inputs & Assumptions'!$H$28="Fixed",'Model Inputs & Assumptions'!$I$28*'Model Inputs & Assumptions'!$K$28,IF('Model Inputs & Assumptions'!$H$28="CPM",'Model Inputs & Assumptions'!$I$28*'Model Inputs & Assumptions'!$K$28*C7/1000,IF('Model Inputs & Assumptions'!$H$28="CPC",'Model Inputs & Assumptions'!$I$28*'Model Inputs & Assumptions'!$K$28*G7,0))) -> 2564.2175 | J7: =H7*INDEX('Model Inputs & Assumptions'!$D$40:$D$42,MATCH('Model Inputs & Assumptions'!$L$28,'Model Inputs & Assumptions'!$A$40:$A$42,0))*INDEX('Model Inputs & Assumptions'!$H$40:$H$42,MATCH('Model Inputs & Assumptions'!$L$28,'Model Inputs & Assumptions'!$A$40:$A$42,0)) -> 117929.65 | K7: =H7*INDEX('Model Inputs & Assumptions'!$G$40:$G$42,MATCH('Model Inputs & Assumptions'!$L$28,'Model Inputs & Assumptions'!$A$40:$A$42,0))*INDEX('Model Inputs & Assumptions'!$H$40:$H$42,MATCH('Model Inputs & Assumptions'!$L$28,'Model Inputs & Assumptions'!$A$40:$A$42,0)) -> 2653.4171 | L7: =IFERROR(K7/I7,0) -> 1.0347863 | M7: =IFERROR(I7/H7,0) -> 184.82077 | N7: ='Model Inputs & Assumptions'!$L$28 -> PRD-EUAI | P7: -0.763451 | Q7: 0.236192 | R7: -0.312608 | S7: -0.360452
A8: 5 | B8: ='Model Inputs & Assumptions'!$B$28 -> finanzen.net — Q1 Awareness Burst | C8: =ROUND(MAX(0,'Model Inputs & Assumptions'!$S$28*EXP('Model Inputs & Assumptions'!$T$28*P8-'Model Inputs & Assumptions'!$T$28^2/2)),0) -> 521100 | D8: =MIN(1,'Model Inputs & Assumptions'!$U$28*EXP('Model Inputs & Assumptions'!$V$28*Q8-'Model Inputs & Assumptions'!$V$28^2/2)) -> 0 | E8: =ROUND(C8*D8,0) -> 0 | F8: =MIN(1,'Model Inputs & Assumptions'!$W$28*EXP('Model Inputs & Assumptions'!$X$28*R8-'Model Inputs & Assumptions'!$X$28^2/2)) -> 0.0014584381 | G8: =ROUND(C8*F8,0) -> 760 | H8: =MAX(0,(C8*'Model Inputs & Assumptions'!$N$28+E8*'Model Inputs & Assumptions'!$O$28+G8*'Model Inputs & Assumptions'!$P$28)*EXP('Model Inputs & Assumptions'!$Q$28*S8-'Model Inputs & Assumptions'!$Q$28^2/2)) -> 14.887019 | I8: =IF('Model Inputs & Assumptions'!$H$28="Fixed",'Model Inputs & Assumptions'!$I$28*'Model Inputs & Assumptions'!$K$28,IF('Model Inputs & Assumptions'!$H$28="CPM",'Model Inputs & Assumptions'!$I$28*'Model Inputs & Assumptions'!$K$28*C8/1000,IF('Model Inputs & Assumptions'!$H$28="CPC",'Model Inputs & Assumptions'!$I$28*'Model Inputs & Assumptions'!$K$28*G8,0))) -> 3387.15 | J8: =H8*INDEX('Model Inputs & Assumptions'!$D$40:$D$42,MATCH('Model Inputs & Assumptions'!$L$28,'Model Inputs & Assumptions'!$A$40:$A$42,0))*INDEX('Model Inputs & Assumptions'!$H$40:$H$42,MATCH('Model Inputs & Assumptions'!$L$28,'Model Inputs & Assumptions'!$A$40:$A$42,0)) -> 126539.66 | K8: =H8*INDEX('Model Inputs & Assumptions'!$G$40:$G$42,MATCH('Model Inputs & Assumptions'!$L$28,'Model Inputs & Assumptions'!$A$40:$A$42,0))*INDEX('Model Inputs & Assumptions'!$H$40:$H$42,MATCH('Model Inputs & Assumptions'!$L$28,'Model Inputs & Assumptions'!$A$40:$A$42,0)) -> 2847.1424 | L8: =IFERROR(K8/I8,0) -> 0.84057169 | M8: =IFERROR(I8/H8,0) -> 227.52372 | N8: ='Model Inputs & Assumptions'!$L$28 -> PRD-EUAI | P8: 0.782859 | Q8: 0.160822 | R8: -0.017723 | S8: -1.270903
A9: 6 | B9: ='Model Inputs & Assumptions'!$B$28 -> finanzen.net — Q1 Awareness Burst | C9: =ROUND(MAX(0,'Model Inputs & Assumptions'!$S$28*EXP('Model Inputs & Assumptions'!$T$28*P9-'Model Inputs & Assumptions'!$T$28^2/2)),0) -> 663031 | D9: =MIN(1,'Model Inputs & Assumptions'!$U$28*EXP('Model Inputs & Assumptions'!$V$28*Q9-'Model Inputs & Assumptions'!$V$28^2/2)) -> 0 | E9: =ROUND(C9*D9,0) -> 0 | F9: =MIN(1,'Model Inputs & Assumptions'!$W$28*EXP('Model Inputs & Assumptions'!$X$28*R9-'Model Inputs & Assumptions'!$X$28^2/2)) -> 0.0012310552 | G9: =ROUND(C9*F9,0) -> 816 | H9: =MAX(0,(C9*'Model Inputs & Assumptions'!$N$28+E9*'Model Inputs & Assumptions'!$O$28+G9*'Model Inputs & Assumptions'!$P$28)*EXP('Model Inputs & Assumptions'!$Q$28*S9-'Model Inputs & Assumptions'!$Q$28^2/2)) -> 20.395983 | I9: =IF('Model Inputs & Assumptions'!$H$28="Fixed",'Model Inputs & Assumptions'!$I$28*'Model Inputs & Assumptions'!$K$28,IF('Model Inputs & Assumptions'!$H$28="CPM",'Model Inputs & Assumptions'!$I$28*'Model Inputs & Assumptions'!$K$28*C9/1000,IF('Model Inputs & Assumptions'!$H$28="CPC",'Model Inputs & Assumptions'!$I$28*'Model Inputs & Assumptions'!$K$28*G9,0))) -> 4309.7015 | J9: =H9*INDEX('Model Inputs & Assumptions'!$D$40:$D$42,MATCH('Model Inputs & Assumptions'!$L$28,'Model Inputs & Assumptions'!$A$40:$A$42,0))*INDEX('Model Inputs & Assumptions'!$H$40:$H$42,MATCH('Model Inputs & Assumptions'!$L$28,'Model Inputs & Assumptions'!$A$40:$A$42,0)) -> 173365.85 | K9: =H9*INDEX('Model Inputs & Assumptions'!$G$40:$G$42,MATCH('Model Inputs & Assumptions'!$L$28,'Model Inputs & Assumptions'!$A$40:$A$42,0))*INDEX('Model Inputs & Assumptions'!$H$40:$H$42,MATCH('Model Inputs & Assumptions'!$L$28,'Model Inputs & Assumptions'!$A$40:$A$42,0)) -> 3900.7317 | L9: =IFERROR(K9/I9,0) -> 0.90510484 | M9: =IFERROR(I9/H9,0) -> 211.30149 | N9: ='Model Inputs & Assumptions'!$L$28 -> PRD-EUAI | P9: 2.121085 | Q9: 0.081547 | R9: -0.788152 | S9: -0.458395
A10: 7 | B10: ='Model Inputs & Assumptions'!$B$28 -> finanzen.net — Q1 Awareness Burst | C10: =ROUND(MAX(0,'Model Inputs & Assumptions'!$S$28*EXP('Model Inputs & Assumptions'!$T$28*P10-'Model Inputs & Assumptions'!$T$28^2/2)),0) -> 412401 | D10: =MIN(1,'Model Inputs & Assumptions'!$U$28*EXP('Model Inputs & Assumptions'!$V$28*Q10-'Model Inputs & Assumptions'!$V$28^2/2)) -> 0 | E10: =ROUND(C10*D10,0) -> 0 | F10: =MIN(1,'Model Inputs & Assumptions'!$W$28*EXP('Model Inputs & Assumptions'!$X$28*R10-'Model Inputs & Assumptions'!$X$28^2/2)) -> 0.0013773283 | G10: =ROUND(C10*F10,0) -> 568 | H10: =MAX(0,(C10*'Model Inputs & Assumptions'!$N$28+E10*'Model Inputs & Assumptions'!$O$28+G10*'Model Inputs & Assumptions'!$P$28)*EXP('Model Inputs & Assumptions'!$Q$28*S10-'Model Inputs & Assumptions'!$Q$28^2/2)) -> 13.743226 | I10: =IF('Model Inputs & Assumptions'!$H$28="Fixed",'Model Inputs & Assumptions'!$I$28*'Model Inputs & Assumptions'!$K$28,IF('Model Inputs & Assumptions'!$H$28="CPM",'Model Inputs & Assumptions'!$I$28*'Model Inputs & Assumptions'!$K$28*C10/1000,IF('Model Inputs & Assumptions'!$H$28="CPC",'Model Inputs & Assumptions'!$I$28*'Model Inputs & Assumptions'!$K$28*G10,0))) -> 2680.6065 | J10: =H10*INDEX('Model Inputs & Assumptions'!$D$40:$D$42,MATCH('Model Inputs & Assumptions'!$L$28,'Model Inputs & Assumptions'!$A$40:$A$42,0))*INDEX('Model Inputs & Assumptions'!$H$40:$H$42,MATCH('Model Inputs & Assumptions'!$L$28,'Model Inputs & Assumptions'!$A$40:$A$42,0)) -> 116817.42 | K10: =H10*INDEX('Model Inputs & Assumptions'!$G$40:$G$42,MATCH('Model Inputs & Assumptions'!$L$28,'Model Inputs & Assumptions'!$A$40:$A$42,0))*INDEX('Model Inputs & Assumptions'!$H$40:$H$42,MATCH('Model Inputs & Assumptions'!$L$28,'Model Inputs & Assumptions'!$A$40:$A$42,0)) -> 2628.3919 | L10: =IFERROR(K10/I10,0) -> 0.98052135 | M10: =IFERROR(I10/H10,0) -> 195.0493 | N10: ='Model Inputs & Assumptions'!$L$28 -> PRD-EUAI | P10: -0.516836 | Q10: 0.654291 | R10: -0.277816 | S10: -0.566725
A11: 8 | B11: ='Model Inputs & Assumptions'!$B$28 -> finanzen.net — Q1 Awareness Burst | C11: =ROUND(MAX(0,'Model Inputs & Assumptions'!$S$28*EXP('Model Inputs & Assumptions'!$T$28*P11-'Model Inputs & Assumptions'!$T$28^2/2)),0) -> 337966 | D11: =MIN(1,'Model Inputs & Assumptions'!$U$28*EXP('Model Inputs & Assumptions'!$V$28*Q11-'Model Inputs & Assumptions'!$V$28^2/2)) -> 0 | E11: =ROUND(C11*D11,0) -> 0 | F11: =MIN(1,'Model Inputs & Assumptions'!$W$28*EXP('Model Inputs & Assumptions'!$X$28*R11-'Model Inputs & Assumptions'!$X$28^2/2)) -> 0.001521883 | G11: =ROUND(C11*F11,0) -> 514 | H11: =MAX(0,(C11*'Model Inputs & Assumptions'!$N$28+E11*'Model Inputs & Assumptions'!$O$28+G11*'Model Inputs & Assumptions'!$P$28)*EXP('Model Inputs & Assumptions'!$Q$28*S11-'Model Inputs & Assumptions'!$Q$28^2/2)) -> 13.127753 | I11: =IF('Model Inputs & Assumptions'!$H$28="Fixed",'Model Inputs & Assumptions'!$I$28*'Model Inputs & Assumptions'!$K$28,IF('Model Inputs & Assumptions'!$H$28="CPM",'Model Inputs & Assumptions'!$I$28*'Model Inputs & Assumptions'!$K$28*C11/1000,IF('Model Inputs & Assumptions'!$H$28="CPC",'Model Inputs & Assumptions'!$I$28*'Model Inputs & Assumptions'!$K$28*G11,0))) -> 2196.779 | J11: =H11*INDEX('Model Inputs & Assumptions'!$D$40:$D$42,MATCH('Model Inputs & Assumptions'!$L$28,'Model Inputs & Assumptions'!$A$40:$A$42,0))*INDEX('Model Inputs & Assumptions'!$H$40:$H$42,MATCH('Model Inputs & Assumptions'!$L$28,'Model Inputs & Assumptions'!$A$40:$A$42,0)) -> 111585.9 | K11: =H11*INDEX('Model Inputs & Assumptions'!$G$40:$G$42,MATCH('Model Inputs & Assumptions'!$L$28,'Model Inputs & Assumptions'!$A$40:$A$42,0))*INDEX('Model Inputs & Assumptions'!$H$40:$H$42,MATCH('Model Inputs & Assumptions'!$L$28,'Model Inputs & Assumptions'!$A$40:$A$42,0)) -> 2510.6828 | L11: =IFERROR(K11/I11,0) -> 1.1428928 | M11: =IFERROR(I11/H11,0) -> 167.33853 | N11: ='Model Inputs & Assumptions'!$L$28 -> PRD-EUAI | P11: -1.622677 | Q11: -1.294824 | R11: 0.175833 | S11: -0.386456
A12: 9 | B12: ='Model Inputs & Assumptions'!$B$28 -> finanzen.net — Q1 Awareness Burst | C12: =ROUND(MAX(0,'Model Inputs & Assumptions'!$S$28*EXP('Model Inputs & Assumptions'!$T$28*P12-'Model Inputs & Assumptions'!$T$28^2/2)),0) -> 693631 | D12: =MIN(1,'Model Inputs & Assumptions'!$U$28*EXP('Model Inputs & Assumptions'!$V$28*Q12-'Model Inputs & Assumptions'!$V$28^2/2)) -> 0 | E12: =ROUND(C12*D12,0) -> 0 | F12: =MIN(1,'Model Inputs & Assumptions'!$W$28*EXP('Model Inputs & Assumptions'!$X$28*R12-'Model Inputs & Assumptions'!$X$28^2/2)) -> 0.0014111562 | G12: =ROUND(C12*F12,0) -> 979 | H12: =MAX(0,(C12*'Model Inputs & Assumptions'!$N$28+E12*'Model Inputs & Assumptions'!$O$28+G12*'Model Inputs & Assumptions'!$P$28)*EXP('Model Inputs & Assumptions'!$Q$28*S12-'Model Inputs & Assumptions'!$Q$28^2/2)) -> 40.370093 | I12: =IF('Model Inputs & Assumptions'!$H$28="Fixed",'Model Inputs & Assumptions'!$I$28*'Model Inputs & Assumptions'!$K$28,IF('Model Inputs & Assumptions'!$H$28="CPM",'Model Inputs & Assumptions'!$I$28*'Model Inputs & Assumptions'!$K$28*C12/1000,IF('Model Inputs & Assumptions'!$H$28="CPC",'Model Inputs & Assumptions'!$I$28*'Model Inputs & Assumptions'!$K$28*G12,0))) -> 4508.6015 | J12: =H12*INDEX('Model Inputs & Assumptions'!$D$40:$D$42,MATCH('Model Inputs & Assumptions'!$L$28,'Model Inputs & Assumptions'!$A$40:$A$42,0))*INDEX('Model Inputs & Assumptions'!$H$40:$H$42,MATCH('Model Inputs & Assumptions'!$L$28,'Model Inputs & Assumptions'!$A$40:$A$42,0)) -> 343145.79 | K12: =H12*INDEX('Model Inputs & Assumptions'!$G$40:$G$42,MATCH('Model Inputs & Assumptions'!$L$28,'Model Inputs & Assumptions'!$A$40:$A$42,0))*INDEX('Model Inputs & Assumptions'!$H$40:$H$42,MATCH('Model Inputs & Assumptions'!$L$28,'Model Inputs & Assumptions'!$A$40:$A$42,0)) -> 7720.7803 | L12: =IFERROR(K12/I12,0) -> 1.7124557 | M12: =IFERROR(I12/H12,0) -> 111.68172 | N12: ='Model Inputs & Assumptions'!$L$28 -> PRD-EUAI | P12: 2.371739 | Q12: 0.051079 | R12: -0.167526 | S12: 1.210385
A13: 10 | B13: ='Model Inputs & Assumptions'!$B$28 -> finanzen.net — Q1 Awareness Burst | C13: =ROUND(MAX(0,'Model Inputs & Assumptions'!$S$28*EXP('Model Inputs & Assumptions'!$T$28*P13-'Model Inputs & Assumptions'!$T$28^2/2)),0) -> 590864 | D13: =MIN(1,'Model Inputs & Assumptions'!$U$28*EXP('Model Inputs & Assumptions'!$V$28*Q13-'Model Inputs & Assumptions'!$V$28^2/2)) -> 0 | E13: =ROUND(C13*D13,0) -> 0 | F13: =MIN(1,'Model Inputs & Assumptions'!$W$28*EXP('Model Inputs & Assumptions'!$X$28*R13-'Model Inputs & Assumptions'!$X$28^2/2)) -> 0.0014223935 | G13: =ROUND(C13*F13,0) -> 840 | H13: =MAX(0,(C13*'Model Inputs & Assumptions'!$N$28+E13*'Model Inputs & Assumptions'!$O$28+G13*'Model Inputs & Assumptions'!$P$28)*EXP('Model Inputs & Assumptions'!$Q$28*S13-'Model Inputs & Assumptions'!$Q$28^2/2)) -> 9.5779166 | I13: =IF('Model Inputs & Assumptions'!$H$28="Fixed",'Model Inputs & Assumptions'!$I$28*'Model Inputs & Assumptions'!$K$28,IF('Model Inputs & Assumptions'!$H$28="CPM",'Model Inputs & Assumptions'!$I$28*'Model Inputs & Assumptions'!$K$28*C13/1000,IF('Model Inputs & Assumptions'!$H$28="CPC",'Model Inputs & Assumptions'!$I$28*'Model Inputs & Assumptions'!$K$28*G13,0))) -> 3840.616 | J13: =H13*INDEX('Model Inputs & Assumptions'!$D$40:$D$42,MATCH('Model Inputs & Assumptions'!$L$28,'Model Inputs & Assumptions'!$A$40:$A$42,0))*INDEX('Model Inputs & Assumptions'!$H$40:$H$42,MATCH('Model Inputs & Assumptions'!$L$28,'Model Inputs & Assumptions'!$A$40:$A$42,0)) -> 81412.291 | K13: =H13*INDEX('Model Inputs & Assumptions'!$G$40:$G$42,MATCH('Model Inputs & Assumptions'!$L$28,'Model Inputs & Assumptions'!$A$40:$A$42,0))*INDEX('Model Inputs & Assumptions'!$H$40:$H$42,MATCH('Model Inputs & Assumptions'!$L$28,'Model Inputs & Assumptions'!$A$40:$A$42,0)) -> 1831.7765 | L13: =IFERROR(K13/I13,0) -> 0.47694863 | M13: =IFERROR(I13/H13,0) -> 400.98658 | N13: ='Model Inputs & Assumptions'!$L$28 -> PRD-EUAI | P13: 1.480889 | Q13: 0.872944 | R13: -0.131473 | S13: -3.074613
A14: 11 | B14: ='Model Inputs & Assumptions'!$B$28 -> finanzen.net — Q1 Awareness Burst | C14: =ROUND(MAX(0,'Model Inputs & Assumptions'!$S$28*EXP('Model Inputs & Assumptions'!$T$28*P14-'Model Inputs & Assumptions'!$T$28^2/2)),0) -> 554044 | D14: =MIN(1,'Model Inputs & Assumptions'!$U$28*EXP('Model Inputs & Assumptions'!$V$28*Q14-'Model Inputs & Assumptions'!$V$28^2/2)) -> 0 | E14: =ROUND(C14*D14,0) -> 0 | F14: =MIN(1,'Model Inputs & Assumptions'!$W$28*EXP('Model Inputs & Assumptions'!$X$28*R14-'Model Inputs & Assumptions'!$X$28^2/2)) -> 0.0012223856 | G14: =ROUND(C14*F14,0) -> 677 | H14: =MAX(0,(C14*'Model Inputs & Assumptions'!$N$28+E14*'Model Inputs & Assumptions'!$O$28+G14*'Model Inputs & Assumptions'!$P$28)*EXP('Model Inputs & Assumptions'!$Q$28*S14-'Model Inputs & Assumptions'!$Q$28^2/2)) -> 18.166819 | I14: =IF('Model Inputs & Assumptions'!$H$28="Fixed",'Model Inputs & Assumptions'!$I$28*'Model Inputs & Assumptions'!$K$28,IF('Model Inputs & Assumptions'!$H$28="CPM",'Model Inputs & Assumptions'!$I$28*'Model Inputs & Assumptions'!$K$28*C14/1000,IF('Model Inputs & Assumptions'!$H$28="CPC",'Model Inputs & Assumptions'!$I$28*'Model Inputs & Assumptions'!$K$28*G14,0))) -> 3601.286 | J14: =H14*INDEX('Model Inputs & Assumptions'!$D$40:$D$42,MATCH('Model Inputs & Assumptions'!$L$28,'Model Inputs & Assumptions'!$A$40:$A$42,0))*INDEX('Model Inputs & Assumptions'!$H$40:$H$42,MATCH('Model Inputs & Assumptions'!$L$28,'Model Inputs & Assumptions'!$A$40:$A$42,0)) -> 154417.96 | K14: =H14*INDEX('Model Inputs & Assumptions'!$G$40:$G$42,MATCH('Model Inputs & Assumptions'!$L$28,'Model Inputs & Assumptions'!$A$40:$A$42,0))*INDEX('Model Inputs & Assumptions'!$H$40:$H$42,MATCH('Model Inputs & Assumptions'!$L$28,'Model Inputs & Assumptions'!$A$40:$A$42,0)) -> 3474.4041 | L14: =IFERROR(K14/I14,0) -> 0.9647676 | M14: =IFERROR(I14/H14,0) -> 198.23427 | N14: ='Model Inputs & Assumptions'!$L$28 -> PRD-EUAI | P14: 1.123428 | Q14: 0.989031 | R14: -0.820276 | S14: -0.221722
